<?xml version="1.0" ?>
<robot name="limo_xacro" xmlns:xacro="http://ros.org/wiki/xacro">


    <link name="base_footprint" />
    <joint name="base_joint" type="fixed">
        <parent link="base_footprint" />
        <child link="base_link" />
        <origin xyz="0.0 0.0 0.15" rpy="0 0 0" />
    </joint>
    <!-- Base link -->
    <link name="base_link">
        <visual>
            <origin xyz="0 0 -0.15" rpy="0 0 1.57" />
            <geometry>
                <mesh filename="package://limo_description/meshes/limo_base.dae" scale="1 1 1" />
            </geometry>
        </visual>
        <collision>
            <!--origin xyz="0 0 -0.15" rpy="0 0 1.57" /-->
            <origin xyz="0 0 0" rpy="0 0 0" />
            <geometry>
                <box size="0.13 0.12 0.1" />
            </geometry>
        </collision>
        <inertial>
            <mass value="0.1" />
            <origin xyz="0 0 0" rpy="0 0 0" />
            <inertia ixx="0.03" iyy="0.03" izz="0.03" ixy="0.0" ixz="0.0" iyz="0.0" />
        </inertial>
    </link>
    <link name="inertial_link">
        <inertial>
            <origin xyz="0.0 0.0 0.0" />
            <mass value="2.1557" />
            <inertia ixx="0.24" ixy="0" ixz="0" iyy="0.96" iyz="0" izz="0.96" />
        </inertial>
    </link>
    <joint name="inertial_joint" type="fixed">
        <origin xyz="0 0 0" rpy="0 0 0" />
        <parent link="base_link" />
        <child link="inertial_link" />
    </joint>
    <link name="front_left_wheel_link">
        <inertial>
            <origin xyz="0.0 0.0 0.0" rpy="0 0 0" />
            <mass value="0.5" />
            <inertia ixx="0.01055" ixy="0" ixz="0" iyy="0.00075" iyz="0" izz="0.01055" />
        </inertial>
        <visual>
            <origin xyz="0 0 0" rpy="0 0 0" />
            <geometry>
                <mesh filename="package://limo_description/meshes/limo_wheel.dae" />
            </geometry>
        </visual>
        <collision>
            <origin xyz="0 0.0225 0" rpy="1.57 0 0" />
            <geometry>
                <cylinder length="0.045" radius="0.045" />
            </geometry>
        </collision>
    </link>
    <joint name="front_left_wheel" type="continuous">
        <parent link="base_link" />
        <child link="front_left_wheel_link" />
        <origin xyz="0.1 0.065 -0.1" rpy="0 0 0" />
        <axis xyz="0 1 0" />
    </joint>
    <link name="front_right_wheel_link">
        <inertial>
            <origin xyz="0.0 0.0 0.0" rpy="0 0 0" />
            <mass value="0.5" />
            <inertia ixx="0.01055" ixy="0" ixz="0" iyy="0.00075" iyz="0" izz="0.01055" />
        </inertial>
        <visual>
            <origin xyz="0 0 0" rpy="0 0 3.14" />
            <geometry>
                <mesh filename="package://limo_description/meshes/limo_wheel.dae" />
            </geometry>
        </visual>
        <collision>
            <origin xyz="0 -0.0225 0" rpy="1.57 0 0" />
            <geometry>
                <cylinder length="0.045" radius="0.045" />
            </geometry>
        </collision>
    </link>
    <joint name="front_right_wheel" type="continuous">
        <parent link="base_link" />
        <child link="front_right_wheel_link" />
        <origin xyz="0.1 -0.065 -0.1" rpy="0 0 0" />
        <axis xyz="0 1 0" />
    </joint>
    <link name="rear_left_wheel_link">
        <inertial>
            <origin xyz="0.0 0.0 0.0 " rpy="0 0 0" />
            <mass value="0.5" />
            <inertia ixx="0.01055" ixy="0" ixz="0" iyy="0.00075" iyz="0" izz="0.01055" />
        </inertial>
        <visual>
            <origin xyz="0 0 0" rpy="0 0 0" />
            <geometry>
                <mesh filename="package://limo_description/meshes/limo_wheel.dae" />
            </geometry>
        </visual>
        <collision>
            <origin xyz="0 0.0225 0" rpy="1.57 0 0" />
            <geometry>
                <cylinder length="0.045" radius="0.045" />
            </geometry>
        </collision>
    </link>
    <joint name="rear_left_wheel" type="continuous">
        <parent link="base_link" />
        <child link="rear_left_wheel_link" />
        <origin xyz="-0.1 0.065 -0.1" rpy="0 0 0" />
        <axis xyz="0 1 0" />
    </joint>
    <link name="rear_right_wheel_link">
        <inertial>
            <origin xyz="0.0 0.0 0.0" rpy="0 0 0" />
            <mass value="0.5" />
            <inertia ixx="0.01055" ixy="0" ixz="0" iyy="0.00075" iyz="0" izz="0.01055" />
        </inertial>
        <visual>
            <origin xyz="0 0 0" rpy="0 0 3.14" />
            <geometry>
                <mesh filename="package://limo_description/meshes/limo_wheel.dae" />
            </geometry>
        </visual>
        <collision>
            <origin xyz="0 -0.0225 0" rpy="1.57 0 0" />
            <geometry>
                <cylinder length="0.045" radius="0.045" />
            </geometry>
        </collision>
    </link>
    <joint name="rear_right_wheel" type="continuous">
        <parent link="base_link" />
        <child link="rear_right_wheel_link" />
        <origin xyz="-0.1 -0.065 -0.1" rpy="0 0 0" />
        <axis xyz="0 1 0" />
    </joint>

       <link name="laser_link">
            <pose>0 0 0 0 0 0</pose>
            <inertial>
                <mass value="0.1"/>
                <origin xyz="0.0 0 0" rpy="0 0 0"/>
                <inertia
                    ixx="1e-6" ixy="0" ixz="0"
                    iyy="1e-6" iyz="0"
                    izz="1e-6"
                />
            </inertial>
            <visual name='laser_visual'>
                <origin xyz="0 0 0" rpy="0 0 0"/>
                <geometry>
                    <cylinder radius="0.02" length="0.01"/>
                </geometry>
                <material name='laser_material'>
                    <ambient>0.1 0.1 0.1 1</ambient>
                    <diffuse>0.1 0.1 0.2 1</diffuse>
                    <specular>0 0 0 0</specular>
                    <emissive>0 0 0 1</emissive>
                </material>
            </visual>
            <collision name='laser_collision'>
                <origin xyz="0 0 0" rpy="0 0 0"/>
                <geometry>
                    <cylinder radius="0.032" length="0.016"/>
                </geometry>
            </collision>
        </link>
        <joint type="fixed" name="laser_joint">
            <origin xyz="0.103 0 -0.034" rpy="0 0 0"/>
            <child link="laser_link"/>
            <parent link="base_link"/>
        </joint>

        <link name="depth_camera_link">
            <pose>0 0 0 0 0 0</pose>
            <inertial>
                <mass value="0.1"/>
                <origin xyz="0.0 0 0" rpy="0 0 0"/>
                <inertia
                    ixx="1e-6" ixy="0" ixz="0"
                    iyy="1e-6" iyz="0"
                    izz="1e-6"
                />
            </inertial>
            <visual name='depth_camera_visual'>
                <origin xyz="0 0 0" rpy="0 0 0"/>
                <geometry>
                    <box size="0.02 0.06 0.015"/>
                </geometry>
                <material name='depth_camera_material'>
                    <ambient>0.1 0.1 0.1 1</ambient>
                    <diffuse>0.1 0.1 0.2 1</diffuse>
                    <specular>0 0 0 0</specular>
                    <emissive>0 0 0 1</emissive>
                </material>
            </visual>
            <collision name='depth_camera_collision'>
                <origin xyz="0 0 0" rpy="0 0 0"/>
                <geometry>
                    <box size="0.02 0.06 0.015"/>
                </geometry>
            </collision>
        </link>
    
        <joint type="fixed" name="depth_camera_joint">
            <origin xyz="0.084 0 0.03" rpy="0 0 0"/>
            <child link="depth_camera_link"/>
            <parent link="base_link"/>
        </joint>
        <link name="depth_link"></link>

        <joint name="depth_camera_to_camera_joint" type="fixed">
            <origin xyz="0 0 0" rpy="-1.57 0 -1.57 "/>
            <parent link="depth_camera_link"/>
            <child link="depth_link"/>
          </joint>

       <link name="imu_link">
            <pose>0 0 0 0 0 0</pose>
            <inertial>
                <mass value="0.01"/>
                <origin xyz="0.0 0 0" rpy="0 0 0"/>
                <inertia
                    ixx="1e-7" ixy="0" ixz="0"
                    iyy="1e-7" iyz="0"
                    izz="1e-7"
                />
            </inertial>
            <visual name='imu_visual'>
                <origin xyz="0 0 0" rpy="0 0 0"/>
                <geometry>
                    <box size="0.001 0.001 0.001"/>
                </geometry>
                <material name='imu_material'>
                    <ambient>0.1 0.1 0.1 1</ambient>
                    <diffuse>0.1 0.1 0.2 1</diffuse>
                    <specular>0 0 0 0</specular>
                    <emissive>0 0 0 1</emissive>
                </material>
            </visual>
            <collision name='imu_collision'>
                <origin xyz="0 0 0" rpy="0 0 0"/>
                <geometry>
                    <box size="0.001 0.001 0.001"/>
                </geometry>
            </collision>
        </link>
        <joint type="fixed" name="imu_joint">
        <origin xyz="0.0 0 -0.1" rpy="0 0 0"/>
            <child link="imu_link"/>
            <parent link="base_link"/>
        </joint>

    <joint name="limo_mycobot" type="fixed">
        <origin xyz="-0.01 0.0 0.0" rpy="0 0 0" />
        <parent link="base_link" />
        <child link="joint1" />
    </joint>
    <link name="joint1">
        <visual>
            <geometry>
                <!--- 0.0 0 -0.04  1.5708 3.14159-->
                <mesh filename="package://mycobot_description/urdf/mycobot/joint1.dae" />
            </geometry>
            <origin xyz="0.0 0 0 " rpy=" 0 0 -1.5708" />
        </visual>
        <collision>
            <geometry>
                <!--- 0.0 0 -0.04  1.5708 3.14159-->
                <mesh filename="package://mycobot_description/urdf/mycobot/joint1.dae" />
            </geometry>
            <origin xyz="0.0 0 0 " rpy=" 0 0 -1.5708" />
        </collision>
        <inertial>
            <mass value="0.1" />
            <origin xyz="0 0 0" rpy="0 0 0" />
            <inertia ixx="0.03" iyy="0.03" izz="0.03" ixy="0.0" ixz="0.0" iyz="0.0" />
        </inertial>
    </link>
    <link name="joint2">
        <visual>
            <geometry>
                <mesh filename="package://mycobot_description/urdf/mycobot/joint2.dae" />
            </geometry>
            <origin xyz="0.0 0 -0.06096 " rpy=" 0 0 -1.5708" />
        </visual>
        <collision>
            <geometry>
                <mesh filename="package://mycobot_description/urdf/mycobot/joint2.dae" />
            </geometry>
            <origin xyz="0.0 0 -0.06096 " rpy=" 0 0 -1.5708" />
        </collision>
        <inertial>
            <mass value="0.1" />
            <origin xyz="0 0 0" rpy="0 0 0" />
            <inertia ixx="0.03" iyy="0.03" izz="0.03" ixy="0.0" ixz="0.0" iyz="0.0" />
        </inertial>
    </link>
    <link name="joint3">
        <visual>
            <geometry>
                <mesh filename="package://mycobot_description/urdf/mycobot/joint3.dae" />
            </geometry>
            <origin xyz="0.0 0 0.03256 " rpy=" 0 -1.5708 0" />
        </visual>
        <collision>
            <geometry>
                <mesh filename="package://mycobot_description/urdf/mycobot/joint3.dae" />
            </geometry>
            <origin xyz="0.0 0 0.03256 " rpy=" 0 -1.5708 0" />
        </collision>
        <inertial>
            <mass value="0.1" />
            <origin xyz="0 0 0" rpy="0 0 0" />
            <inertia ixx="0.03" iyy="0.03" izz="0.03" ixy="0.0" ixz="0.0" iyz="0.0" />
        </inertial>
    </link>
    <link name="joint4">
        <visual>
            <geometry>
                <!--- 0.0 0 -0.04 -->
                <mesh filename="package://mycobot_description/urdf/mycobot/joint4.dae" />
            </geometry>
            <origin xyz="0.0 0 0.03056 " rpy=" 0 -1.5708 0" />
        </visual>
        <collision>
            <geometry>
                <!--- 0.0 0 -0.04 -->
                <mesh filename="package://mycobot_description/urdf/mycobot/joint4.dae" />
            </geometry>
            <origin xyz="0.0 0 0.03056 " rpy=" 0 -1.5708 0" />
        </collision>
        <inertial>
            <mass value="0.1" />
            <origin xyz="0 0 0" rpy="0 0 0" />
            <inertia ixx="0.03" iyy="0.03" izz="0.03" ixy="0.0" ixz="0.0" iyz="0.0" />
        </inertial>
    </link>
    <link name="joint5">
        <visual>
            <geometry>
                <!--- 0.0 0 -0.04 -->
                <mesh filename="package://mycobot_description/urdf/mycobot/joint5.dae" />
            </geometry>
            <origin xyz="0.0 0 -0.03356 " rpy=" -1.5708 0 0" />
        </visual>
        <collision>
            <geometry>
                <!--- 0.0 0 -0.04 -->
                <mesh filename="package://mycobot_description/urdf/mycobot/joint5.dae" />
            </geometry>
            <origin xyz="0.0 0 -0.03356 " rpy=" -1.5708 0 0" />
        </collision>
        <inertial>
            <mass value="0.1" />
            <origin xyz="0 0 0" rpy="0 0 0" />
            <inertia ixx="0.03" iyy="0.03" izz="0.03" ixy="0.0" ixz="0.0" iyz="0.0" />
        </inertial>
    </link>
    <link name="joint6">
        <visual>
            <geometry>
                <!--- 0.0 0 -0.04 -->
                <mesh filename="package://mycobot_description/urdf/mycobot/joint6.dae" />
            </geometry>
            <origin xyz="0 0.00 -0.038 " rpy=" 0 0 0" />
        </visual>
        <collision>
            <geometry>
                <!--- 0.0 0 -0.04 -->
                <mesh filename="package://mycobot_description/urdf/mycobot/joint6.dae" />
            </geometry>
            <origin xyz="0 0.00 -0.038 " rpy=" 0 0 0" />
        </collision>
        <inertial>
            <mass value="0.1" />
            <origin xyz="0 0 0" rpy="0 0 0" />
            <inertia ixx="0.03" iyy="0.03" izz="0.03" ixy="0.0" ixz="0.0" iyz="0.0" />
        </inertial>
    </link>
    <link name="joint6_flange">
        <visual>
            <geometry>
                <!--- 0.0 0 -0.04 -->
                <mesh filename="package://mycobot_description/urdf/mycobot/joint7.dae" />
            </geometry>
            <origin xyz="0.0 0 -0.012 " rpy=" 0 0 0" />
        </visual>
        <collision>
            <geometry>
                <!--- 0.0 0 -0.04 -->
                <mesh filename="package://mycobot_description/urdf/mycobot/joint7.dae" />
            </geometry>
            <origin xyz="0.0 0 -0.012 " rpy=" 0 0 0" />
        </collision>
        <inertial>
            <mass value="0.1" />
            <origin xyz="0 0 0" rpy="0 0 0" />
            <inertia ixx="0.03" iyy="0.03" izz="0.03" ixy="0.0" ixz="0.0" iyz="0.0" />
        </inertial>
    </link>
    <joint name="joint2_to_joint1" type="revolute">
        <axis xyz="0 0 1" />
        <limit effort="1000.0" lower="-3.14" upper="3.14159" velocity="10" />
        <parent link="joint1" />
        <child link="joint2" />
        <origin xyz="0 0 0.13156" rpy="0 0 0" />
    </joint>
    <joint name="joint3_to_joint2" type="revolute">
        <axis xyz="0 0 1" />
        <limit effort="1000.0" lower="-3.14" upper="3.14159" velocity="10" />
        <parent link="joint2" />
        <child link="joint3" />
        <origin xyz="0 0  0" rpy="0 1.5708 -1.5708" />
    </joint>
    <joint name="joint4_to_joint3" type="revolute">
        <axis xyz=" 0 0 1" />
        <limit effort="1000.0" lower="-3.14" upper="3.14159" velocity="10" />
        <parent link="joint3" />
        <child link="joint4" />
        <origin xyz="  -0.1104 0 0   " rpy="0 0 0" />
    </joint>
    <joint name="joint5_to_joint4" type="revolute">
        <axis xyz=" 0 0 1" />
        <limit effort="1000.0" lower="-3.14" upper="3.14159" velocity="10" />
        <parent link="joint4" />
        <child link="joint5" />
        <origin xyz="-0.096 0 0.06462" rpy="0 0 -1.5708" />
    </joint>
    <joint name="joint6_to_joint5" type="revolute">
        <axis xyz="0 0 1" />
        <limit effort="1000.0" lower="-3.14" upper="3.14159" velocity="10" />
        <parent link="joint5" />
        <child link="joint6" />
        <origin xyz="0 -0.07318 0" rpy="1.5708 -1.5708 0" />
    </joint>
    <joint name="joint6output_to_joint6" type="revolute">
        <axis xyz="0 0 1" />
        <limit effort="1000.0" lower="-3.14" upper="3.14159" velocity="10" />
        <parent link="joint6" />
        <child link="joint6_flange" />
        <origin xyz="0 0.0456 0" rpy="-1.5708 0 0" />
    </joint>
    <link name="gripper_finger_link1">
        <visual>
            <origin xyz="0.0 0.0 0" />
            <geometry>
                <box size="0.04 0.01 0.01" />
            </geometry>
        </visual>
        <collision>
            <geometry>
                <box size="0.04 0.01 0.01" />
            </geometry>
        </collision>
        <inertial>
            <mass value="0.1" />
            <origin xyz="0 0 0" rpy="0 0 0" />
            <inertia ixx="0.03" iyy="0.03" izz="0.03" ixy="0.0" ixz="0.0" iyz="0.0" />
        </inertial>
    </link>
    <joint name="finger_joint2" type="fixed">
        <parent link="joint6_flange" />
        <child link="gripper_finger_link1" />
        <origin xyz="-0.02 0 0.02" rpy="0.0 1.57 0.0" />
    </joint>
    <!-- RIGHT GRIPPER AFT LINK -->
    <link name="gripper_finger_link2">
        <visual>
            <origin xyz="0.0 0.0 0" />
            <geometry>
                <box size="0.04 0.01 0.01" />
            </geometry>
        </visual>
        <collision>
            <geometry>
                <box size="0.04 0.01 0.01" />
            </geometry>
        </collision>
        <inertial>
            <mass value="0.1" />
            <origin xyz="0 0 0" rpy="0 0 0" />
            <inertia ixx="0.03" iyy="0.03" izz="0.03" ixy="0.0" ixz="0.0" iyz="0.0" />
        </inertial>
    </link>
    <joint name="grasping_frame_joint" type="prismatic">
        <parent link="joint6_flange" />
        <child link="gripper_finger_link2" />
        <origin xyz="0.02 0.0 0.02" rpy="0.0 1.57 0.0" />
        <limit effort="1000.0" lower="-0.03" upper="0.0" velocity="10" />
        <axis xyz="0 0 1" />
    </joint>

    <transmission name="trans_front_left_wheel">
        <type>transmission_interface/SimpleTransmission</type>
        <joint name="front_left_wheel">
            <hardwareInterface>hardware_interface/EffortJointInterface</hardwareInterface>
        </joint>
        <actuator name="front_left_wheel_motor">
            <hardwareInterface>hardware_interface/EffortJointInterface</hardwareInterface>
            <mechanicalReduction>1</mechanicalReduction>
        </actuator>
    </transmission>
    <transmission name="trans_front_right_wheel">
        <type>transmission_interface/SimpleTransmission</type>
        <joint name="front_right_wheel">
            <hardwareInterface>hardware_interface/EffortJointInterface</hardwareInterface>
        </joint>
        <actuator name="front_right_wheel_motor">
            <hardwareInterface>hardware_interface/EffortJointInterface</hardwareInterface>
            <mechanicalReduction>1</mechanicalReduction>
        </actuator>
    </transmission>
    <transmission name="trans_rear_left_wheel">
        <type>transmission_interface/SimpleTransmission</type>
        <joint name="rear_left_wheel">
            <hardwareInterface>hardware_interface/EffortJointInterface</hardwareInterface>
        </joint>
        <actuator name="rear_left_wheel_motor">
            <hardwareInterface>hardware_interface/EffortJointInterface</hardwareInterface>
            <mechanicalReduction>1</mechanicalReduction>
        </actuator>
    </transmission>
    <transmission name="trans_rear_right_wheel">
        <type>transmission_interface/SimpleTransmission</type>
        <joint name="rear_right_wheel">
            <hardwareInterface>hardware_interface/EffortJointInterface</hardwareInterface>
        </joint>
        <actuator name="rear_right_wheel_motor">
            <hardwareInterface>hardware_interface/EffortJointInterface</hardwareInterface>
            <mechanicalReduction>1</mechanicalReduction>
        </actuator>
    </transmission>
    <transmission name="trans_joint2_to_joint1">
        <type>transmission_interface/SimpleTransmission</type>
        <joint name="joint2_to_joint1">
            <hardwareInterface>hardware_interface/EffortJointInterface</hardwareInterface>
        </joint>
        <actuator name="joint2_to_joint1_motor">
            <hardwareInterface>hardware_interface/EffortJointInterface</hardwareInterface>
            <mechanicalReduction>1</mechanicalReduction>
        </actuator>
    </transmission>
    <transmission name="trans_joint3_to_joint2">
        <type>transmission_interface/SimpleTransmission</type>
        <joint name="joint3_to_joint2">
            <hardwareInterface>hardware_interface/EffortJointInterface</hardwareInterface>
        </joint>
        <actuator name="joint3_to_joint2_motor">
            <hardwareInterface>hardware_interface/EffortJointInterface</hardwareInterface>
            <mechanicalReduction>1</mechanicalReduction>
        </actuator>
    </transmission>
    <transmission name="trans_joint4_to_joint3">
        <type>transmission_interface/SimpleTransmission</type>
        <joint name="joint4_to_joint3">
            <hardwareInterface>hardware_interface/EffortJointInterface</hardwareInterface>
        </joint>
        <actuator name="joint4_to_joint3_motor">
            <hardwareInterface>hardware_interface/EffortJointInterface</hardwareInterface>
            <mechanicalReduction>1</mechanicalReduction>
        </actuator>
    </transmission>
    <transmission name="trans_joint5_to_joint4">
        <type>transmission_interface/SimpleTransmission</type>
        <joint name="joint5_to_joint4">
            <hardwareInterface>hardware_interface/EffortJointInterface</hardwareInterface>
        </joint>
        <actuator name="joint5_to_joint4_motor">
            <hardwareInterface>hardware_interface/EffortJointInterface</hardwareInterface>
            <mechanicalReduction>1</mechanicalReduction>
        </actuator>
    </transmission>
    <transmission name="trans_joint6_to_joint5">
        <type>transmission_interface/SimpleTransmission</type>
        <joint name="joint6_to_joint5">
            <hardwareInterface>hardware_interface/EffortJointInterface</hardwareInterface>
        </joint>
        <actuator name="joint6_to_joint5_motor">
            <hardwareInterface>hardware_interface/EffortJointInterface</hardwareInterface>
            <mechanicalReduction>1</mechanicalReduction>
        </actuator>
    </transmission>
    <transmission name="trans_joint6output_to_joint6">
        <type>transmission_interface/SimpleTransmission</type>
        <joint name="joint6output_to_joint6">
            <hardwareInterface>hardware_interface/EffortJointInterface</hardwareInterface>
        </joint>
        <actuator name="joint6output_to_joint6_motor">
            <hardwareInterface>hardware_interface/EffortJointInterface</hardwareInterface>
            <mechanicalReduction>1</mechanicalReduction>
        </actuator>
    </transmission>

    <transmission name="trans_grasping_frame_joint">
        <type>transmission_interface/SimpleTransmission</type>
        <joint name="grasping_frame_joint">
            <hardwareInterface>hardware_interface/EffortJointInterface</hardwareInterface>
        </joint>
        <actuator name="grasping_frame_joint_motor">
            <hardwareInterface>hardware_interface/EffortJointInterface</hardwareInterface>
            <mechanicalReduction>1</mechanicalReduction>
        </actuator>
    </transmission>

    <gazebo>
        <plugin name="gazebo_ros_control" filename="libgazebo_ros_control.so">
            <robotNamespace>/</robotNamespace>
        </plugin>
    </gazebo>


    <gazebo>

        <plugin name="four_diff_controller" filename="libgazebo_ros_skid_steer_drive.so">
            <updateRate>50.0</updateRate>
            <robotNamespace>/</robotNamespace>
            <leftFrontJoint>front_left_wheel</leftFrontJoint>
            <rightFrontJoint>front_right_wheel</rightFrontJoint>
            <leftRearJoint>rear_left_wheel</leftRearJoint>
            <rightRearJoint>rear_right_wheel</rightRearJoint>
            <wheelSeparation>0.172</wheelSeparation>
            <wheelDiameter>0.09</wheelDiameter>
            <robotBaseFrame>base_footprint</robotBaseFrame>
            <commandTopic>cmd_vel</commandTopic>
            <torque>50</torque>
            <broadcastTF>true</broadcastTF>
            <odometryTopic>odom</odometryTopic>
            <odometryFrame>odom</odometryFrame>
            <covariance_x>0.000100</covariance_x>
            <covariance_y>0.000100</covariance_y>
            <covariance_yaw>0.010000</covariance_yaw>
        </plugin>
    </gazebo>

        <gazebo reference="laser_link">
            <sensor type="ray" name="laser_sensor">
              <pose>0 0 0 0 0 0</pose>
              <visualize>false</visualize>
              <update_rate>8</update_rate>
              <ray>
                <scan>
                  <horizontal>
                    <samples>720</samples>
                    <resolution>1</resolution>
                    <min_angle>-2.09439504</min_angle>
                    <max_angle>2.09439504</max_angle>
                  </horizontal>
                </scan>
                <range>
                  <min>0.05</min>
                  <max>8.0</max>
                  <resolution>0.01</resolution>
                </range>
                <noise>
                  <type>gaussian</type>
                  <mean>0.0</mean>
                  <stddev>0.01</stddev>
                </noise>
              </ray>
              <plugin name="gazebo_ros_laser_sensor" filename="libgazebo_ros_laser.so">
                <topicName>/limo/scan</topicName>
                <frameName>laser_link</frameName>
              </plugin>
            </sensor>
          </gazebo>


        <gazebo reference="depth_camera_link">
          <sensor name="sensor_camera" type="depth">
            <pose>0.0 0.0 0.0 0.0 0.0 0.0</pose>
            <always_on>true</always_on>
            <visualize>true</visualize>
            <update_rate>10.0</update_rate>
            <camera name="head">
              <horizontal_fov>1.3962634</horizontal_fov>
              <image>
                  <width>640</width>
                  <height>480</height>
                  <format>R8G8B8</format>
              </image>
              <clip>
                  <near>0.02</near>
                  <far>300</far>
              </clip>
            </camera>

            <plugin name="gazebo_ros_depth_camera_sensor" filename="libgazebo_ros_openni_kinect.so">
              <baseline>0.2</baseline>
              <alwaysOn>true</alwaysOn>
              <!-- Keep this zero, update_rate in the parent <sensor> tag
                will control the frame rate. -->
              <updateRate>0.0</updateRate>
              <cameraName>camera_ir</cameraName>
              <imageTopicName>/limo/color/image_raw</imageTopicName>
              <cameraInfoTopicName>/limo/color/camera_info</cameraInfoTopicName>
              <depthImageTopicName>/limo/depth/image_raw</depthImageTopicName>
              <depthImageCameraInfoTopicName>/limo/depth/camera_info</depthImageCameraInfoTopicName>
              <pointCloudTopicName>/limo/depth/points</pointCloudTopicName>
              <frameName>depth_link</frameName>
              <cameraname>depth_camera_link</cameraname>
              
              <pointCloudCutoff>0.5</pointCloudCutoff>
              <pointCloudCutoffMax>3.0</pointCloudCutoffMax>
              <distortionK1>0</distortionK1>
              <distortionK2>0</distortionK2>
              <distortionK3>0</distortionK3>
              <distortionT1>0</distortionT1>
              <distortionT2>0</distortionT2>
              <CxPrime>0</CxPrime>
              <Cx>0</Cx>
              <Cy>0</Cy>
              <focalLength>0</focalLength>
              <hackBaseline>0</hackBaseline>
            </plugin>
        </sensor>
          </gazebo>

      <gazebo reference="imu_link">
        <gravity>true</gravity>
        <sensor name="imu_sensor" type="imu">
          <always_on>true</always_on>
          <update_rate>100</update_rate>
          <visualize>true</visualize>
          <topic>__default_topic__</topic>
          <plugin filename="libgazebo_ros_imu_sensor.so" name="imu_plugin">
            <topicName>/limo/imu</topicName>
            <bodyName>${frame_prefix}_link</bodyName>
            <updateRateHZ>100.0</updateRateHZ>
            <gaussianNoise>0.001</gaussianNoise>
            <xyzOffset>0 0 0</xyzOffset>
            <rpyOffset>0 0 0</rpyOffset>
            <frameName>imu_link</frameName>
          </plugin>
          <pose>0 0 0 0 0 0</pose>
        </sensor>
      </gazebo>
</robot>

